[2024-03-06T03:02:00.708+0000] {task_context_logger.py:104} ERROR - Executor reports task instance <TaskInstance: extract_api.extract_data manual__2024-03-06T03:01:58.866926+00:00 [queued]> finished (failed) although the task says it's queued. (Info: None) Was the task killed externally?
