[2024-03-06T03:30:56.825+0000] {taskinstance.py:1979} INFO - Dependencies all met for dep_context=non-requeueable deps ti=<TaskInstance: extract_api.python_connector manual__2024-03-06T03:29:51.358184+00:00 [queued]>
[2024-03-06T03:30:56.833+0000] {taskinstance.py:1979} INFO - Dependencies all met for dep_context=requeueable deps ti=<TaskInstance: extract_api.python_connector manual__2024-03-06T03:29:51.358184+00:00 [queued]>
[2024-03-06T03:30:56.834+0000] {taskinstance.py:2193} INFO - Starting attempt 1 of 1
[2024-03-06T03:30:56.847+0000] {taskinstance.py:2214} INFO - Executing <Task(PythonOperator): python_connector> on 2024-03-06 03:29:51.358184+00:00
[2024-03-06T03:30:56.854+0000] {standard_task_runner.py:60} INFO - Started process 1289 to run task
[2024-03-06T03:30:56.856+0000] {standard_task_runner.py:87} INFO - Running: ['***', 'tasks', 'run', 'extract_api', 'python_connector', 'manual__2024-03-06T03:29:51.358184+00:00', '--job-id', '97', '--raw', '--subdir', 'DAGS_FOLDER/bix_dag.py', '--cfg-path', '/tmp/tmpnzuu4od7']
[2024-03-06T03:30:56.857+0000] {standard_task_runner.py:88} INFO - Job 97: Subtask python_connector
[2024-03-06T03:30:56.900+0000] {task_command.py:423} INFO - Running <TaskInstance: extract_api.python_connector manual__2024-03-06T03:29:51.358184+00:00 [running]> on host 474cfb7f4723
[2024-03-06T03:30:57.005+0000] {taskinstance.py:2510} INFO - Exporting env vars: AIRFLOW_CTX_DAG_OWNER='***' AIRFLOW_CTX_DAG_ID='extract_api' AIRFLOW_CTX_TASK_ID='python_connector' AIRFLOW_CTX_EXECUTION_DATE='2024-03-06T03:29:51.358184+00:00' AIRFLOW_CTX_TRY_NUMBER='1' AIRFLOW_CTX_DAG_RUN_ID='manual__2024-03-06T03:29:51.358184+00:00'
[2024-03-06T03:30:57.007+0000] {taskinstance.py:2728} ERROR - Task failed with exception
Traceback (most recent call last):
  File "/home/airflow/.local/lib/python3.11/site-packages/airflow/models/taskinstance.py", line 444, in _execute_task
    result = _execute_callable(context=context, **execute_callable_kwargs)
             ^^^^^^^^^^^^^^^^^^^^^^^^^^^^^^^^^^^^^^^^^^^^^^^^^^^^^^^^^^^^^
  File "/home/airflow/.local/lib/python3.11/site-packages/airflow/models/taskinstance.py", line 414, in _execute_callable
    return execute_callable(context=context, **execute_callable_kwargs)
           ^^^^^^^^^^^^^^^^^^^^^^^^^^^^^^^^^^^^^^^^^^^^^^^^^^^^^^^^^^^^
  File "/home/airflow/.local/lib/python3.11/site-packages/airflow/operators/python.py", line 200, in execute
    return_value = self.execute_callable()
                   ^^^^^^^^^^^^^^^^^^^^^^^
  File "/home/airflow/.local/lib/python3.11/site-packages/airflow/operators/python.py", line 217, in execute_callable
    return self.python_callable(*self.op_args, **self.op_kwargs)
           ^^^^^^^^^^^^^^^^^^^^^^^^^^^^^^^^^^^^^^^^^^^^^^^^^^^^^
TypeError: python_connector() takes 0 positional arguments but 1 was given
[2024-03-06T03:30:57.015+0000] {taskinstance.py:1149} INFO - Marking task as FAILED. dag_id=extract_api, task_id=python_connector, execution_date=20240306T032951, start_date=20240306T033056, end_date=20240306T033057
[2024-03-06T03:30:57.026+0000] {standard_task_runner.py:107} ERROR - Failed to execute job 97 for task python_connector (python_connector() takes 0 positional arguments but 1 was given; 1289)
[2024-03-06T03:30:57.069+0000] {local_task_job_runner.py:234} INFO - Task exited with return code 1
[2024-03-06T03:30:57.084+0000] {taskinstance.py:3309} INFO - 0 downstream tasks scheduled from follow-on schedule check
