[2024-03-04T00:40:28.558+0000] {task_context_logger.py:104} ERROR - Executor reports task instance <TaskInstance: extract_api.extract_data scheduled__2024-03-03T00:00:00+00:00 [queued]> finished (failed) although the task says it's queued. (Info: None) Was the task killed externally?
