[2024-03-06T13:28:39.122+0000] {task_context_logger.py:104} WARNING - Marking task instance <TaskInstance: extract_api.extract_data manual__2024-03-06T13:17:41.302952+00:00 [queued]> stuck in queued as failed. If the task instance has available retries, it will be retried.
[2024-03-06T13:28:39.269+0000] {task_context_logger.py:104} ERROR - Executor reports task instance <TaskInstance: extract_api.extract_data manual__2024-03-06T13:17:41.302952+00:00 [queued]> finished (failed) although the task says it's queued. (Info: None) Was the task killed externally?
