[2024-03-06T14:59:02.827+0000] {taskinstance.py:1979} INFO - Dependencies all met for dep_context=non-requeueable deps ti=<TaskInstance: extract_api.python_connector manual__2024-03-06T14:58:19.744321+00:00 [queued]>
[2024-03-06T14:59:02.835+0000] {taskinstance.py:1979} INFO - Dependencies all met for dep_context=requeueable deps ti=<TaskInstance: extract_api.python_connector manual__2024-03-06T14:58:19.744321+00:00 [queued]>
[2024-03-06T14:59:02.836+0000] {taskinstance.py:2193} INFO - Starting attempt 1 of 1
[2024-03-06T14:59:02.849+0000] {taskinstance.py:2214} INFO - Executing <Task(PythonOperator): python_connector> on 2024-03-06 14:58:19.744321+00:00
[2024-03-06T14:59:02.855+0000] {standard_task_runner.py:60} INFO - Started process 512 to run task
[2024-03-06T14:59:02.858+0000] {standard_task_runner.py:87} INFO - Running: ['***', 'tasks', 'run', 'extract_api', 'python_connector', 'manual__2024-03-06T14:58:19.744321+00:00', '--job-id', '112', '--raw', '--subdir', 'DAGS_FOLDER/bix_dag.py', '--cfg-path', '/tmp/tmp3xhow3eq']
[2024-03-06T14:59:02.859+0000] {standard_task_runner.py:88} INFO - Job 112: Subtask python_connector
[2024-03-06T14:59:02.901+0000] {task_command.py:423} INFO - Running <TaskInstance: extract_api.python_connector manual__2024-03-06T14:58:19.744321+00:00 [running]> on host 474cfb7f4723
[2024-03-06T14:59:03.016+0000] {taskinstance.py:2510} INFO - Exporting env vars: AIRFLOW_CTX_DAG_OWNER='***' AIRFLOW_CTX_DAG_ID='extract_api' AIRFLOW_CTX_TASK_ID='python_connector' AIRFLOW_CTX_EXECUTION_DATE='2024-03-06T14:58:19.744321+00:00' AIRFLOW_CTX_TRY_NUMBER='1' AIRFLOW_CTX_DAG_RUN_ID='manual__2024-03-06T14:58:19.744321+00:00'
[2024-03-06T14:59:03.018+0000] {taskinstance.py:2728} ERROR - Task failed with exception
Traceback (most recent call last):
  File "/home/airflow/.local/lib/python3.11/site-packages/airflow/models/taskinstance.py", line 444, in _execute_task
    result = _execute_callable(context=context, **execute_callable_kwargs)
             ^^^^^^^^^^^^^^^^^^^^^^^^^^^^^^^^^^^^^^^^^^^^^^^^^^^^^^^^^^^^^
  File "/home/airflow/.local/lib/python3.11/site-packages/airflow/models/taskinstance.py", line 414, in _execute_callable
    return execute_callable(context=context, **execute_callable_kwargs)
           ^^^^^^^^^^^^^^^^^^^^^^^^^^^^^^^^^^^^^^^^^^^^^^^^^^^^^^^^^^^^
  File "/home/airflow/.local/lib/python3.11/site-packages/airflow/operators/python.py", line 200, in execute
    return_value = self.execute_callable()
                   ^^^^^^^^^^^^^^^^^^^^^^^
  File "/home/airflow/.local/lib/python3.11/site-packages/airflow/operators/python.py", line 217, in execute_callable
    return self.python_callable(*self.op_args, **self.op_kwargs)
           ^^^^^^^^^^^^^^^^^^^^^^^^^^^^^^^^^^^^^^^^^^^^^^^^^^^^^
TypeError: python_connector() takes 0 positional arguments but 1 was given
[2024-03-06T14:59:03.026+0000] {taskinstance.py:1149} INFO - Marking task as FAILED. dag_id=extract_api, task_id=python_connector, execution_date=20240306T145819, start_date=20240306T145902, end_date=20240306T145903
[2024-03-06T14:59:03.039+0000] {standard_task_runner.py:107} ERROR - Failed to execute job 112 for task python_connector (python_connector() takes 0 positional arguments but 1 was given; 512)
[2024-03-06T14:59:03.072+0000] {local_task_job_runner.py:234} INFO - Task exited with return code 1
[2024-03-06T14:59:03.093+0000] {taskinstance.py:3309} INFO - 0 downstream tasks scheduled from follow-on schedule check
