[2024-03-06T02:29:11.200+0000] {taskinstance.py:1979} INFO - Dependencies all met for dep_context=non-requeueable deps ti=<TaskInstance: extract_api.python_connector manual__2024-03-06T02:28:31.494756+00:00 [queued]>
[2024-03-06T02:29:11.210+0000] {taskinstance.py:1979} INFO - Dependencies all met for dep_context=requeueable deps ti=<TaskInstance: extract_api.python_connector manual__2024-03-06T02:28:31.494756+00:00 [queued]>
[2024-03-06T02:29:11.211+0000] {taskinstance.py:2193} INFO - Starting attempt 1 of 1
[2024-03-06T02:29:11.222+0000] {taskinstance.py:2214} INFO - Executing <Task(PythonOperator): python_connector> on 2024-03-06 02:28:31.494756+00:00
[2024-03-06T02:29:11.229+0000] {standard_task_runner.py:60} INFO - Started process 403 to run task
[2024-03-06T02:29:11.231+0000] {standard_task_runner.py:87} INFO - Running: ['***', 'tasks', 'run', 'extract_api', 'python_connector', 'manual__2024-03-06T02:28:31.494756+00:00', '--job-id', '83', '--raw', '--subdir', 'DAGS_FOLDER/bix_dag.py', '--cfg-path', '/tmp/tmps5o3loh9']
[2024-03-06T02:29:11.232+0000] {standard_task_runner.py:88} INFO - Job 83: Subtask python_connector
[2024-03-06T02:29:11.273+0000] {task_command.py:423} INFO - Running <TaskInstance: extract_api.python_connector manual__2024-03-06T02:28:31.494756+00:00 [running]> on host 474cfb7f4723
[2024-03-06T02:29:11.375+0000] {taskinstance.py:2510} INFO - Exporting env vars: AIRFLOW_CTX_DAG_OWNER='***' AIRFLOW_CTX_DAG_ID='extract_api' AIRFLOW_CTX_TASK_ID='python_connector' AIRFLOW_CTX_EXECUTION_DATE='2024-03-06T02:28:31.494756+00:00' AIRFLOW_CTX_TRY_NUMBER='1' AIRFLOW_CTX_DAG_RUN_ID='manual__2024-03-06T02:28:31.494756+00:00'
[2024-03-06T02:29:11.377+0000] {taskinstance.py:2728} ERROR - Task failed with exception
Traceback (most recent call last):
  File "/home/airflow/.local/lib/python3.11/site-packages/airflow/models/taskinstance.py", line 444, in _execute_task
    result = _execute_callable(context=context, **execute_callable_kwargs)
             ^^^^^^^^^^^^^^^^^^^^^^^^^^^^^^^^^^^^^^^^^^^^^^^^^^^^^^^^^^^^^
  File "/home/airflow/.local/lib/python3.11/site-packages/airflow/models/taskinstance.py", line 414, in _execute_callable
    return execute_callable(context=context, **execute_callable_kwargs)
           ^^^^^^^^^^^^^^^^^^^^^^^^^^^^^^^^^^^^^^^^^^^^^^^^^^^^^^^^^^^^
  File "/home/airflow/.local/lib/python3.11/site-packages/airflow/operators/python.py", line 200, in execute
    return_value = self.execute_callable()
                   ^^^^^^^^^^^^^^^^^^^^^^^
  File "/home/airflow/.local/lib/python3.11/site-packages/airflow/operators/python.py", line 217, in execute_callable
    return self.python_callable(*self.op_args, **self.op_kwargs)
           ^^^^^^^^^^^^^^^^^^^^^^^^^^^^^^^^^^^^^^^^^^^^^^^^^^^^^
TypeError: python_connector() takes 0 positional arguments but 1 was given
[2024-03-06T02:29:11.384+0000] {taskinstance.py:1149} INFO - Marking task as FAILED. dag_id=extract_api, task_id=python_connector, execution_date=20240306T022831, start_date=20240306T022911, end_date=20240306T022911
[2024-03-06T02:29:11.394+0000] {standard_task_runner.py:107} ERROR - Failed to execute job 83 for task python_connector (python_connector() takes 0 positional arguments but 1 was given; 403)
[2024-03-06T02:29:11.404+0000] {local_task_job_runner.py:234} INFO - Task exited with return code 1
[2024-03-06T02:29:11.418+0000] {taskinstance.py:3309} INFO - 0 downstream tasks scheduled from follow-on schedule check
