[2024-03-06T02:14:14.390+0000] {taskinstance.py:1979} INFO - Dependencies all met for dep_context=non-requeueable deps ti=<TaskInstance: extract_api.extract_data scheduled__2024-03-05T00:00:00+00:00 [queued]>
[2024-03-06T02:14:14.398+0000] {taskinstance.py:1979} INFO - Dependencies all met for dep_context=requeueable deps ti=<TaskInstance: extract_api.extract_data scheduled__2024-03-05T00:00:00+00:00 [queued]>
[2024-03-06T02:14:14.399+0000] {taskinstance.py:2193} INFO - Starting attempt 1 of 1
[2024-03-06T02:14:14.414+0000] {taskinstance.py:2214} INFO - Executing <Task(PythonOperator): extract_data> on 2024-03-05 00:00:00+00:00
[2024-03-06T02:14:14.420+0000] {standard_task_runner.py:60} INFO - Started process 145 to run task
[2024-03-06T02:14:14.422+0000] {standard_task_runner.py:87} INFO - Running: ['***', 'tasks', 'run', 'extract_api', 'extract_data', 'scheduled__2024-03-05T00:00:00+00:00', '--job-id', '70', '--raw', '--subdir', 'DAGS_FOLDER/bix_dag.py', '--cfg-path', '/tmp/tmpcgifkikd']
[2024-03-06T02:14:14.426+0000] {standard_task_runner.py:88} INFO - Job 70: Subtask extract_data
[2024-03-06T02:14:14.473+0000] {task_command.py:423} INFO - Running <TaskInstance: extract_api.extract_data scheduled__2024-03-05T00:00:00+00:00 [running]> on host 474cfb7f4723
[2024-03-06T02:14:14.556+0000] {taskinstance.py:2510} INFO - Exporting env vars: AIRFLOW_CTX_DAG_OWNER='***' AIRFLOW_CTX_DAG_ID='extract_api' AIRFLOW_CTX_TASK_ID='extract_data' AIRFLOW_CTX_EXECUTION_DATE='2024-03-05T00:00:00+00:00' AIRFLOW_CTX_TRY_NUMBER='1' AIRFLOW_CTX_DAG_RUN_ID='scheduled__2024-03-05T00:00:00+00:00'
[2024-03-06T02:14:14.559+0000] {taskinstance.py:2728} ERROR - Task failed with exception
Traceback (most recent call last):
  File "/home/airflow/.local/lib/python3.11/site-packages/airflow/models/taskinstance.py", line 444, in _execute_task
    result = _execute_callable(context=context, **execute_callable_kwargs)
             ^^^^^^^^^^^^^^^^^^^^^^^^^^^^^^^^^^^^^^^^^^^^^^^^^^^^^^^^^^^^^
  File "/home/airflow/.local/lib/python3.11/site-packages/airflow/models/taskinstance.py", line 414, in _execute_callable
    return execute_callable(context=context, **execute_callable_kwargs)
           ^^^^^^^^^^^^^^^^^^^^^^^^^^^^^^^^^^^^^^^^^^^^^^^^^^^^^^^^^^^^
  File "/home/airflow/.local/lib/python3.11/site-packages/airflow/operators/python.py", line 200, in execute
    return_value = self.execute_callable()
                   ^^^^^^^^^^^^^^^^^^^^^^^
  File "/home/airflow/.local/lib/python3.11/site-packages/airflow/operators/python.py", line 217, in execute_callable
    return self.python_callable(*self.op_args, **self.op_kwargs)
           ^^^^^^^^^^^^^^^^^^^^^^^^^^^^^^^^^^^^^^^^^^^^^^^^^^^^^
  File "/opt/airflow/dags/bix_dag.py", line 8, in extract_data_from_api
    extract_data_from_api = extract_data_from_api()
                            ^^^^^^^^^^^^^^^^^^^^^
UnboundLocalError: cannot access local variable 'extract_data_from_api' where it is not associated with a value
[2024-03-06T02:14:14.575+0000] {taskinstance.py:1149} INFO - Marking task as FAILED. dag_id=extract_api, task_id=extract_data, execution_date=20240305T000000, start_date=20240306T021414, end_date=20240306T021414
[2024-03-06T02:14:14.602+0000] {standard_task_runner.py:107} ERROR - Failed to execute job 70 for task extract_data (cannot access local variable 'extract_data_from_api' where it is not associated with a value; 145)
[2024-03-06T02:14:14.636+0000] {local_task_job_runner.py:234} INFO - Task exited with return code 1
[2024-03-06T02:14:14.674+0000] {taskinstance.py:3309} INFO - 0 downstream tasks scheduled from follow-on schedule check
