[2024-03-03T18:28:54.620+0000] {taskinstance.py:1979} INFO - Dependencies all met for dep_context=non-requeueable deps ti=<TaskInstance: extract_api.extract_data scheduled__2024-03-02T00:00:00+00:00 [queued]>
[2024-03-03T18:28:54.627+0000] {taskinstance.py:1979} INFO - Dependencies all met for dep_context=requeueable deps ti=<TaskInstance: extract_api.extract_data scheduled__2024-03-02T00:00:00+00:00 [queued]>
[2024-03-03T18:28:54.628+0000] {taskinstance.py:2193} INFO - Starting attempt 1 of 1
[2024-03-03T18:28:54.642+0000] {taskinstance.py:2214} INFO - Executing <Task(PythonOperator): extract_data> on 2024-03-02 00:00:00+00:00
[2024-03-03T18:28:54.647+0000] {standard_task_runner.py:60} INFO - Started process 168 to run task
[2024-03-03T18:28:54.650+0000] {standard_task_runner.py:87} INFO - Running: ['***', 'tasks', 'run', 'extract_api', 'extract_data', 'scheduled__2024-03-02T00:00:00+00:00', '--job-id', '5', '--raw', '--subdir', 'DAGS_FOLDER/from_bard.py', '--cfg-path', '/tmp/tmpp5dawk2j']
[2024-03-03T18:28:54.651+0000] {standard_task_runner.py:88} INFO - Job 5: Subtask extract_data
[2024-03-03T18:28:54.697+0000] {task_command.py:423} INFO - Running <TaskInstance: extract_api.extract_data scheduled__2024-03-02T00:00:00+00:00 [running]> on host aabe39a25c19
[2024-03-03T18:28:54.764+0000] {taskinstance.py:2510} INFO - Exporting env vars: AIRFLOW_CTX_DAG_OWNER='***' AIRFLOW_CTX_DAG_ID='extract_api' AIRFLOW_CTX_TASK_ID='extract_data' AIRFLOW_CTX_EXECUTION_DATE='2024-03-02T00:00:00+00:00' AIRFLOW_CTX_TRY_NUMBER='1' AIRFLOW_CTX_DAG_RUN_ID='scheduled__2024-03-02T00:00:00+00:00'
[2024-03-03T18:28:57.390+0000] {taskinstance.py:2728} ERROR - Task failed with exception
Traceback (most recent call last):
  File "/home/airflow/.local/lib/python3.11/site-packages/requests/models.py", line 971, in json
    return complexjson.loads(self.text, **kwargs)
           ^^^^^^^^^^^^^^^^^^^^^^^^^^^^^^^^^^^^^^
  File "/usr/local/lib/python3.11/json/__init__.py", line 346, in loads
    return _default_decoder.decode(s)
           ^^^^^^^^^^^^^^^^^^^^^^^^^^
  File "/usr/local/lib/python3.11/json/decoder.py", line 340, in decode
    raise JSONDecodeError("Extra data", s, end)
json.decoder.JSONDecodeError: Extra data: line 1 column 5 (char 4)

During handling of the above exception, another exception occurred:

Traceback (most recent call last):
  File "/home/airflow/.local/lib/python3.11/site-packages/airflow/models/taskinstance.py", line 444, in _execute_task
    result = _execute_callable(context=context, **execute_callable_kwargs)
             ^^^^^^^^^^^^^^^^^^^^^^^^^^^^^^^^^^^^^^^^^^^^^^^^^^^^^^^^^^^^^
  File "/home/airflow/.local/lib/python3.11/site-packages/airflow/models/taskinstance.py", line 414, in _execute_callable
    return execute_callable(context=context, **execute_callable_kwargs)
           ^^^^^^^^^^^^^^^^^^^^^^^^^^^^^^^^^^^^^^^^^^^^^^^^^^^^^^^^^^^^
  File "/home/airflow/.local/lib/python3.11/site-packages/airflow/operators/python.py", line 200, in execute
    return_value = self.execute_callable()
                   ^^^^^^^^^^^^^^^^^^^^^^^
  File "/home/airflow/.local/lib/python3.11/site-packages/airflow/operators/python.py", line 217, in execute_callable
    return self.python_callable(*self.op_args, **self.op_kwargs)
           ^^^^^^^^^^^^^^^^^^^^^^^^^^^^^^^^^^^^^^^^^^^^^^^^^^^^^
  File "/opt/airflow/dags/from_bard.py", line 14, in extract_data_from_api
    data = response.json()
           ^^^^^^^^^^^^^^^
  File "/home/airflow/.local/lib/python3.11/site-packages/requests/models.py", line 975, in json
    raise RequestsJSONDecodeError(e.msg, e.doc, e.pos)
requests.exceptions.JSONDecodeError: Extra data: line 1 column 5 (char 4)
[2024-03-03T18:28:57.400+0000] {taskinstance.py:1149} INFO - Marking task as FAILED. dag_id=extract_api, task_id=extract_data, execution_date=20240302T000000, start_date=20240303T182854, end_date=20240303T182857
[2024-03-03T18:28:57.413+0000] {standard_task_runner.py:107} ERROR - Failed to execute job 5 for task extract_data (Extra data: line 1 column 5 (char 4); 168)
[2024-03-03T18:28:57.435+0000] {local_task_job_runner.py:234} INFO - Task exited with return code 1
[2024-03-03T18:28:57.455+0000] {taskinstance.py:3309} INFO - 0 downstream tasks scheduled from follow-on schedule check
