[2024-03-04T23:13:46.419+0000] {taskinstance.py:1979} INFO - Dependencies all met for dep_context=non-requeueable deps ti=<TaskInstance: extract_api.ingest_data manual__2024-03-04T23:12:59.458056+00:00 [queued]>
[2024-03-04T23:13:46.427+0000] {taskinstance.py:1979} INFO - Dependencies all met for dep_context=requeueable deps ti=<TaskInstance: extract_api.ingest_data manual__2024-03-04T23:12:59.458056+00:00 [queued]>
[2024-03-04T23:13:46.428+0000] {taskinstance.py:2193} INFO - Starting attempt 1 of 1
[2024-03-04T23:13:46.440+0000] {taskinstance.py:2214} INFO - Executing <Task(PythonOperator): ingest_data> on 2024-03-04 23:12:59.458056+00:00
[2024-03-04T23:13:46.447+0000] {standard_task_runner.py:60} INFO - Started process 684 to run task
[2024-03-04T23:13:46.449+0000] {standard_task_runner.py:87} INFO - Running: ['***', 'tasks', 'run', 'extract_api', 'ingest_data', 'manual__2024-03-04T23:12:59.458056+00:00', '--job-id', '39', '--raw', '--subdir', 'DAGS_FOLDER/from_bard.py', '--cfg-path', '/tmp/tmpan0rmh7h']
[2024-03-04T23:13:46.451+0000] {standard_task_runner.py:88} INFO - Job 39: Subtask ingest_data
[2024-03-04T23:13:46.493+0000] {task_command.py:423} INFO - Running <TaskInstance: extract_api.ingest_data manual__2024-03-04T23:12:59.458056+00:00 [running]> on host 474cfb7f4723
[2024-03-04T23:13:46.602+0000] {taskinstance.py:2510} INFO - Exporting env vars: AIRFLOW_CTX_DAG_OWNER='***' AIRFLOW_CTX_DAG_ID='extract_api' AIRFLOW_CTX_TASK_ID='ingest_data' AIRFLOW_CTX_EXECUTION_DATE='2024-03-04T23:12:59.458056+00:00' AIRFLOW_CTX_TRY_NUMBER='1' AIRFLOW_CTX_DAG_RUN_ID='manual__2024-03-04T23:12:59.458056+00:00'
[2024-03-04T23:13:46.604+0000] {connection.py:386} INFO - Snowflake Connector for Python Version: 3.7.1, Python Version: 3.11.8, Platform: Linux-5.15.133.1-microsoft-standard-WSL2-x86_64-with-glibc2.36
[2024-03-04T23:13:46.614+0000] {taskinstance.py:2728} ERROR - Task failed with exception
Traceback (most recent call last):
  File "/home/airflow/.local/lib/python3.11/site-packages/airflow/models/taskinstance.py", line 444, in _execute_task
    result = _execute_callable(context=context, **execute_callable_kwargs)
             ^^^^^^^^^^^^^^^^^^^^^^^^^^^^^^^^^^^^^^^^^^^^^^^^^^^^^^^^^^^^^
  File "/home/airflow/.local/lib/python3.11/site-packages/airflow/models/taskinstance.py", line 414, in _execute_callable
    return execute_callable(context=context, **execute_callable_kwargs)
           ^^^^^^^^^^^^^^^^^^^^^^^^^^^^^^^^^^^^^^^^^^^^^^^^^^^^^^^^^^^^
  File "/home/airflow/.local/lib/python3.11/site-packages/airflow/operators/python.py", line 200, in execute
    return_value = self.execute_callable()
                   ^^^^^^^^^^^^^^^^^^^^^^^
  File "/home/airflow/.local/lib/python3.11/site-packages/airflow/operators/python.py", line 217, in execute_callable
    return self.python_callable(*self.op_args, **self.op_kwargs)
           ^^^^^^^^^^^^^^^^^^^^^^^^^^^^^^^^^^^^^^^^^^^^^^^^^^^^^
  File "/opt/airflow/dags/from_bard.py", line 69, in ingest_data_to_snowflake
    ctx = connect(
          ^^^^^^^^
  File "/home/airflow/.local/lib/python3.11/site-packages/snowflake/connector/__init__.py", line 54, in Connect
    return SnowflakeConnection(**kwargs)
           ^^^^^^^^^^^^^^^^^^^^^^^^^^^^^
  File "/home/airflow/.local/lib/python3.11/site-packages/snowflake/connector/connection.py", line 429, in __init__
    self.connect(**kwargs)
  File "/home/airflow/.local/lib/python3.11/site-packages/snowflake/connector/connection.py", line 683, in connect
    self.__config(**kwargs)
  File "/home/airflow/.local/lib/python3.11/site-packages/snowflake/connector/connection.py", line 1160, in __config
    Error.errorhandler_wrapper(
  File "/home/airflow/.local/lib/python3.11/site-packages/snowflake/connector/errors.py", line 290, in errorhandler_wrapper
    handed_over = Error.hand_to_other_handler(
                  ^^^^^^^^^^^^^^^^^^^^^^^^^^^^
  File "/home/airflow/.local/lib/python3.11/site-packages/snowflake/connector/errors.py", line 348, in hand_to_other_handler
    connection.errorhandler(connection, cursor, error_class, error_value)
  File "/home/airflow/.local/lib/python3.11/site-packages/snowflake/connector/errors.py", line 221, in default_errorhandler
    raise error_class(
snowflake.connector.errors.ProgrammingError: 251005: 251005: User is empty
[2024-03-04T23:13:46.623+0000] {taskinstance.py:1149} INFO - Marking task as FAILED. dag_id=extract_api, task_id=ingest_data, execution_date=20240304T231259, start_date=20240304T231346, end_date=20240304T231346
[2024-03-04T23:13:46.635+0000] {standard_task_runner.py:107} ERROR - Failed to execute job 39 for task ingest_data (251005: 251005: User is empty; 684)
[2024-03-04T23:13:46.663+0000] {local_task_job_runner.py:234} INFO - Task exited with return code 1
[2024-03-04T23:13:46.678+0000] {taskinstance.py:3309} INFO - 0 downstream tasks scheduled from follow-on schedule check
