[2024-03-06T02:33:08.439+0000] {taskinstance.py:1979} INFO - Dependencies all met for dep_context=non-requeueable deps ti=<TaskInstance: extract_api.python_connector manual__2024-03-06T02:32:28.971690+00:00 [queued]>
[2024-03-06T02:33:08.448+0000] {taskinstance.py:1979} INFO - Dependencies all met for dep_context=requeueable deps ti=<TaskInstance: extract_api.python_connector manual__2024-03-06T02:32:28.971690+00:00 [queued]>
[2024-03-06T02:33:08.449+0000] {taskinstance.py:2193} INFO - Starting attempt 1 of 1
[2024-03-06T02:33:08.462+0000] {taskinstance.py:2214} INFO - Executing <Task(PythonOperator): python_connector> on 2024-03-06 02:32:28.971690+00:00
[2024-03-06T02:33:08.468+0000] {standard_task_runner.py:60} INFO - Started process 489 to run task
[2024-03-06T02:33:08.470+0000] {standard_task_runner.py:87} INFO - Running: ['***', 'tasks', 'run', 'extract_api', 'python_connector', 'manual__2024-03-06T02:32:28.971690+00:00', '--job-id', '89', '--raw', '--subdir', 'DAGS_FOLDER/bix_dag.py', '--cfg-path', '/tmp/tmpk5zcokxa']
[2024-03-06T02:33:08.472+0000] {standard_task_runner.py:88} INFO - Job 89: Subtask python_connector
[2024-03-06T02:33:08.516+0000] {task_command.py:423} INFO - Running <TaskInstance: extract_api.python_connector manual__2024-03-06T02:32:28.971690+00:00 [running]> on host 474cfb7f4723
[2024-03-06T02:33:08.642+0000] {taskinstance.py:2510} INFO - Exporting env vars: AIRFLOW_CTX_DAG_OWNER='***' AIRFLOW_CTX_DAG_ID='extract_api' AIRFLOW_CTX_TASK_ID='python_connector' AIRFLOW_CTX_EXECUTION_DATE='2024-03-06T02:32:28.971690+00:00' AIRFLOW_CTX_TRY_NUMBER='1' AIRFLOW_CTX_DAG_RUN_ID='manual__2024-03-06T02:32:28.971690+00:00'
[2024-03-06T02:33:08.644+0000] {taskinstance.py:2728} ERROR - Task failed with exception
Traceback (most recent call last):
  File "/home/airflow/.local/lib/python3.11/site-packages/airflow/models/taskinstance.py", line 444, in _execute_task
    result = _execute_callable(context=context, **execute_callable_kwargs)
             ^^^^^^^^^^^^^^^^^^^^^^^^^^^^^^^^^^^^^^^^^^^^^^^^^^^^^^^^^^^^^
  File "/home/airflow/.local/lib/python3.11/site-packages/airflow/models/taskinstance.py", line 414, in _execute_callable
    return execute_callable(context=context, **execute_callable_kwargs)
           ^^^^^^^^^^^^^^^^^^^^^^^^^^^^^^^^^^^^^^^^^^^^^^^^^^^^^^^^^^^^
  File "/home/airflow/.local/lib/python3.11/site-packages/airflow/operators/python.py", line 200, in execute
    return_value = self.execute_callable()
                   ^^^^^^^^^^^^^^^^^^^^^^^
  File "/home/airflow/.local/lib/python3.11/site-packages/airflow/operators/python.py", line 217, in execute_callable
    return self.python_callable(*self.op_args, **self.op_kwargs)
           ^^^^^^^^^^^^^^^^^^^^^^^^^^^^^^^^^^^^^^^^^^^^^^^^^^^^^
TypeError: python_connector() takes 0 positional arguments but 1 was given
[2024-03-06T02:33:08.652+0000] {taskinstance.py:1149} INFO - Marking task as FAILED. dag_id=extract_api, task_id=python_connector, execution_date=20240306T023228, start_date=20240306T023308, end_date=20240306T023308
[2024-03-06T02:33:08.665+0000] {standard_task_runner.py:107} ERROR - Failed to execute job 89 for task python_connector (python_connector() takes 0 positional arguments but 1 was given; 489)
[2024-03-06T02:33:08.683+0000] {local_task_job_runner.py:234} INFO - Task exited with return code 1
[2024-03-06T02:33:08.710+0000] {taskinstance.py:3309} INFO - 0 downstream tasks scheduled from follow-on schedule check
