[2024-03-03T20:58:12.783+0000] {taskinstance.py:1979} INFO - Dependencies all met for dep_context=non-requeueable deps ti=<TaskInstance: extract_api.extract_data manual__2024-03-03T20:57:52.529597+00:00 [queued]>
[2024-03-03T20:58:12.791+0000] {taskinstance.py:1979} INFO - Dependencies all met for dep_context=requeueable deps ti=<TaskInstance: extract_api.extract_data manual__2024-03-03T20:57:52.529597+00:00 [queued]>
[2024-03-03T20:58:12.791+0000] {taskinstance.py:2193} INFO - Starting attempt 1 of 1
[2024-03-03T20:58:12.804+0000] {taskinstance.py:2214} INFO - Executing <Task(PythonOperator): extract_data> on 2024-03-03 20:57:52.529597+00:00
[2024-03-03T20:58:12.810+0000] {standard_task_runner.py:60} INFO - Started process 155 to run task
[2024-03-03T20:58:12.812+0000] {standard_task_runner.py:87} INFO - Running: ['***', 'tasks', 'run', 'extract_api', 'extract_data', 'manual__2024-03-03T20:57:52.529597+00:00', '--job-id', '16', '--raw', '--subdir', 'DAGS_FOLDER/from_bard.py', '--cfg-path', '/tmp/tmpd2atoj_6']
[2024-03-03T20:58:12.813+0000] {standard_task_runner.py:88} INFO - Job 16: Subtask extract_data
[2024-03-03T20:58:12.851+0000] {task_command.py:423} INFO - Running <TaskInstance: extract_api.extract_data manual__2024-03-03T20:57:52.529597+00:00 [running]> on host aabe39a25c19
[2024-03-03T20:58:12.909+0000] {taskinstance.py:2510} INFO - Exporting env vars: AIRFLOW_CTX_DAG_OWNER='***' AIRFLOW_CTX_DAG_ID='extract_api' AIRFLOW_CTX_TASK_ID='extract_data' AIRFLOW_CTX_EXECUTION_DATE='2024-03-03T20:57:52.529597+00:00' AIRFLOW_CTX_TRY_NUMBER='1' AIRFLOW_CTX_DAG_RUN_ID='manual__2024-03-03T20:57:52.529597+00:00'
[2024-03-03T20:58:12.911+0000] {taskinstance.py:2728} ERROR - Task failed with exception
Traceback (most recent call last):
  File "/home/airflow/.local/lib/python3.11/site-packages/airflow/models/taskinstance.py", line 444, in _execute_task
    result = _execute_callable(context=context, **execute_callable_kwargs)
             ^^^^^^^^^^^^^^^^^^^^^^^^^^^^^^^^^^^^^^^^^^^^^^^^^^^^^^^^^^^^^
  File "/home/airflow/.local/lib/python3.11/site-packages/airflow/models/taskinstance.py", line 414, in _execute_callable
    return execute_callable(context=context, **execute_callable_kwargs)
           ^^^^^^^^^^^^^^^^^^^^^^^^^^^^^^^^^^^^^^^^^^^^^^^^^^^^^^^^^^^^
  File "/home/airflow/.local/lib/python3.11/site-packages/airflow/operators/python.py", line 200, in execute
    return_value = self.execute_callable()
                   ^^^^^^^^^^^^^^^^^^^^^^^
  File "/home/airflow/.local/lib/python3.11/site-packages/airflow/operators/python.py", line 217, in execute_callable
    return self.python_callable(*self.op_args, **self.op_kwargs)
           ^^^^^^^^^^^^^^^^^^^^^^^^^^^^^^^^^^^^^^^^^^^^^^^^^^^^^
  File "/opt/airflow/dags/from_bard.py", line 24, in extract_data_from_api
    data = response.text()
           ^^^^^^^^^^^^^^^
TypeError: 'str' object is not callable
[2024-03-03T20:58:12.922+0000] {taskinstance.py:1149} INFO - Marking task as FAILED. dag_id=extract_api, task_id=extract_data, execution_date=20240303T205752, start_date=20240303T205812, end_date=20240303T205812
[2024-03-03T20:58:12.933+0000] {standard_task_runner.py:107} ERROR - Failed to execute job 16 for task extract_data ('str' object is not callable; 155)
[2024-03-03T20:58:12.945+0000] {local_task_job_runner.py:234} INFO - Task exited with return code 1
[2024-03-03T20:58:12.962+0000] {taskinstance.py:3309} INFO - 0 downstream tasks scheduled from follow-on schedule check
